2025-05-08 05:56:31|ERROR   |root                            |Error trying to get announcements from Github. Connection Error.|'Traceback (most recent call last):\n  File "/app/bazarr/bin/bazarr/../libs/urllib3/connection.py", line 198, in _new_conn\n    sock = connection.create_connection(\n           ^^^^^^^^^^^^^^^^^^^^^^^^^^^^^\n  File "/app/bazarr/bin/bazarr/../custom_libs/subliminal_patch/http.py", line 325, in patched_create_connection\n    return _orig_create_connection(address, *args, **kwargs)\n           ^^^^^^^^^^^^^^^^^^^^^^^^^^^^^^^^^^^^^^^^^^^^^^^^^\n  File "/app/bazarr/bin/bazarr/../libs/urllib3/util/connection.py", line 85, in create_connection\n    raise err\n  File "/app/bazarr/bin/bazarr/../libs/urllib3/util/connection.py", line 73, in create_connection\n    sock.connect(sa)\nOSError: [Errno 101] Network unreachable\n\nThe above exception was the direct cause of the following exception:\n\nTraceback (most recent call last):\n  File "/app/bazarr/bin/bazarr/../libs/urllib3/connectionpool.py", line 793, in urlopen\n    response = self._make_request(\n               ^^^^^^^^^^^^^^^^^^^\n  File "/app/bazarr/bin/bazarr/../libs/urllib3/connectionpool.py", line 491, in _make_request\n    raise new_e\n  File "/app/bazarr/bin/bazarr/../libs/urllib3/connectionpool.py", line 467, in _make_request\n    self._validate_conn(conn)\n  File "/app/bazarr/bin/bazarr/../libs/urllib3/connectionpool.py", line 1099, in _validate_conn\n    conn.connect()\n  File "/app/bazarr/bin/bazarr/../libs/urllib3/connection.py", line 616, in connect\n    self.sock = sock = self._new_conn()\n                       ^^^^^^^^^^^^^^^^\n  File "/app/bazarr/bin/bazarr/../libs/urllib3/connection.py", line 213, in _new_conn\n    raise NewConnectionError(\nurllib3.exceptions.NewConnectionError: <urllib3.connection.HTTPSConnection object at 0x7fc6efd43b30>: Failed to establish a new connection: [Errno 101] Network unreachable\n\nThe above exception was the direct cause of the following exception:\n\nTraceback (most recent call last):\n  File "/app/bazarr/bin/bazarr/../libs/requests/adapters.py", line 486, in send\n    resp = conn.urlopen(\n           ^^^^^^^^^^^^^\n  File "/app/bazarr/bin/bazarr/../libs/urllib3/connectionpool.py", line 847, in urlopen\n    retries = retries.increment(\n              ^^^^^^^^^^^^^^^^^^\n  File "/app/bazarr/bin/bazarr/../libs/urllib3/util/retry.py", line 515, in increment\n    raise MaxRetryError(_pool, url, reason) from reason  # type: ignore[arg-type]\n    ^^^^^^^^^^^^^^^^^^^^^^^^^^^^^^^^^^^^^^^^^^^^^^^^^^^\nurllib3.exceptions.MaxRetryError: HTTPSConnectionPool(host=\'raw.githubusercontent.com\', port=443): Max retries exceeded with url: /morpheus65535/bazarr-binaries/master/announcements.json (Caused by NewConnectionError(\'<urllib3.connection.HTTPSConnection object at 0x7fc6efd43b30>: Failed to establish a new connection: [Errno 101] Network unreachable\'))\n\nDuring handling of the above exception, another exception occurred:\n\nTraceback (most recent call last):\n  File "/app/bazarr/bin/bazarr/app/announcements.py", line 46, in get_announcements_to_file\n    r = requests.get("https://raw.githubusercontent.com/morpheus65535/bazarr-binaries/master/announcements.json",\n        ^^^^^^^^^^^^^^^^^^^^^^^^^^^^^^^^^^^^^^^^^^^^^^^^^^^^^^^^^^^^^^^^^^^^^^^^^^^^^^^^^^^^^^^^^^^^^^^^^^^^^^^^^\n  File "/app/bazarr/bin/bazarr/../libs/requests/api.py", line 73, in get\n    return request("get", url, params=params, **kwargs)\n           ^^^^^^^^^^^^^^^^^^^^^^^^^^^^^^^^^^^^^^^^^^^^\n  File "/app/bazarr/bin/bazarr/../libs/requests/api.py", line 59, in request\n    return session.request(method=method, url=url, **kwargs)\n           ^^^^^^^^^^^^^^^^^^^^^^^^^^^^^^^^^^^^^^^^^^^^^^^^^\n  File "/app/bazarr/bin/bazarr/../libs/requests/sessions.py", line 589, in request\n    resp = self.send(prep, **send_kwargs)\n           ^^^^^^^^^^^^^^^^^^^^^^^^^^^^^^\n  File "/app/bazarr/bin/bazarr/../libs/requests/sessions.py", line 703, in send\n    r = adapter.send(request, **kwargs)\n        ^^^^^^^^^^^^^^^^^^^^^^^^^^^^^^^\n  File "/app/bazarr/bin/bazarr/../libs/requests/adapters.py", line 519, in send\n    raise ConnectionError(e, request=request)\nrequests.exceptions.ConnectionError: HTTPSConnectionPool(host=\'raw.githubusercontent.com\', port=443): Max retries exceeded with url: /morpheus65535/bazarr-binaries/master/announcements.json (Caused by NewConnectionError(\'<urllib3.connection.HTTPSConnection object at 0x7fc6efd43b30>: Failed to establish a new connection: [Errno 101] Network unreachable\'))'|
2025-05-08 05:56:47|ERROR   |root                            |Error trying to get releases from Github. Connection Error.|'Traceback (most recent call last):\n  File "/app/bazarr/bin/bazarr/../libs/urllib3/connection.py", line 198, in _new_conn\n    sock = connection.create_connection(\n           ^^^^^^^^^^^^^^^^^^^^^^^^^^^^^\n  File "/app/bazarr/bin/bazarr/../custom_libs/subliminal_patch/http.py", line 325, in patched_create_connection\n    return _orig_create_connection(address, *args, **kwargs)\n           ^^^^^^^^^^^^^^^^^^^^^^^^^^^^^^^^^^^^^^^^^^^^^^^^^\n  File "/app/bazarr/bin/bazarr/../libs/urllib3/util/connection.py", line 85, in create_connection\n    raise err\n  File "/app/bazarr/bin/bazarr/../libs/urllib3/util/connection.py", line 73, in create_connection\n    sock.connect(sa)\nTimeoutError: timed out\n\nThe above exception was the direct cause of the following exception:\n\nTraceback (most recent call last):\n  File "/app/bazarr/bin/bazarr/../libs/urllib3/connectionpool.py", line 793, in urlopen\n    response = self._make_request(\n               ^^^^^^^^^^^^^^^^^^^\n  File "/app/bazarr/bin/bazarr/../libs/urllib3/connectionpool.py", line 491, in _make_request\n    raise new_e\n  File "/app/bazarr/bin/bazarr/../libs/urllib3/connectionpool.py", line 467, in _make_request\n    self._validate_conn(conn)\n  File "/app/bazarr/bin/bazarr/../libs/urllib3/connectionpool.py", line 1099, in _validate_conn\n    conn.connect()\n  File "/app/bazarr/bin/bazarr/../libs/urllib3/connection.py", line 616, in connect\n    self.sock = sock = self._new_conn()\n                       ^^^^^^^^^^^^^^^^\n  File "/app/bazarr/bin/bazarr/../libs/urllib3/connection.py", line 207, in _new_conn\n    raise ConnectTimeoutError(\nurllib3.exceptions.ConnectTimeoutError: (<urllib3.connection.HTTPSConnection object at 0x7fc6ef6712e0>, \'Connection to api.github.com timed out. (connect timeout=15)\')\n\nThe above exception was the direct cause of the following exception:\n\nTraceback (most recent call last):\n  File "/app/bazarr/bin/bazarr/../libs/requests/adapters.py", line 486, in send\n    resp = conn.urlopen(\n           ^^^^^^^^^^^^^\n  File "/app/bazarr/bin/bazarr/../libs/urllib3/connectionpool.py", line 847, in urlopen\n    retries = retries.increment(\n              ^^^^^^^^^^^^^^^^^^\n  File "/app/bazarr/bin/bazarr/../libs/urllib3/util/retry.py", line 515, in increment\n    raise MaxRetryError(_pool, url, reason) from reason  # type: ignore[arg-type]\n    ^^^^^^^^^^^^^^^^^^^^^^^^^^^^^^^^^^^^^^^^^^^^^^^^^^^\nurllib3.exceptions.MaxRetryError: HTTPSConnectionPool(host=\'api.github.com\', port=443): Max retries exceeded with url: /repos/morpheus65535/Bazarr/releases?per_page=100 (Caused by ConnectTimeoutError(<urllib3.connection.HTTPSConnection object at 0x7fc6ef6712e0>, \'Connection to api.github.com timed out. (connect timeout=15)\'))\n\nDuring handling of the above exception, another exception occurred:\n\nTraceback (most recent call last):\n  File "/app/bazarr/bin/bazarr/app/check_update.py", line 28, in check_releases\n    r = requests.get(url_releases, allow_redirects=True, timeout=15)\n        ^^^^^^^^^^^^^^^^^^^^^^^^^^^^^^^^^^^^^^^^^^^^^^^^^^^^^^^^^^^^\n  File "/app/bazarr/bin/bazarr/../libs/requests/api.py", line 73, in get\n    return request("get", url, params=params, **kwargs)\n           ^^^^^^^^^^^^^^^^^^^^^^^^^^^^^^^^^^^^^^^^^^^^\n  File "/app/bazarr/bin/bazarr/../libs/requests/api.py", line 59, in request\n    return session.request(method=method, url=url, **kwargs)\n           ^^^^^^^^^^^^^^^^^^^^^^^^^^^^^^^^^^^^^^^^^^^^^^^^^\n  File "/app/bazarr/bin/bazarr/../libs/requests/sessions.py", line 589, in request\n    resp = self.send(prep, **send_kwargs)\n           ^^^^^^^^^^^^^^^^^^^^^^^^^^^^^^\n  File "/app/bazarr/bin/bazarr/../libs/requests/sessions.py", line 703, in send\n    r = adapter.send(request, **kwargs)\n        ^^^^^^^^^^^^^^^^^^^^^^^^^^^^^^^\n  File "/app/bazarr/bin/bazarr/../libs/requests/adapters.py", line 507, in send\n    raise ConnectTimeout(e, request=request)\nrequests.exceptions.ConnectTimeout: HTTPSConnectionPool(host=\'api.github.com\', port=443): Max retries exceeded with url: /repos/morpheus65535/Bazarr/releases?per_page=100 (Caused by ConnectTimeoutError(<urllib3.connection.HTTPSConnection object at 0x7fc6ef6712e0>, \'Connection to api.github.com timed out. (connect timeout=15)\'))'|
2025-05-08 05:57:07|INFO    |waitress                        |BAZARR is started and waiting for requests on: http://***.***.***.***:6767|
2025-05-08 05:57:07|INFO    |waitress                        |BAZARR is started and waiting for requests on: http://[::]:6767|
2025-05-08 11:58:25|INFO    |root                            |Successful authentication from ***.***.***.*** for user n30x|
2025-05-08 14:58:38|INFO    |root                            |Successful authentication from ***.***.***.*** for user n30x|
2025-05-08 15:00:35|INFO    |root                            |BAZARR trying to connect to Sonarr SignalR feed...|
2025-05-08 15:00:35|INFO    |root                            |BAZARR SignalR client for Sonarr is connected and waiting for events.|
2025-05-08 15:01:40|INFO    |root                            |BAZARR trying to connect to Radarr SignalR feed...|
2025-05-08 15:01:40|INFO    |root                            |BAZARR SignalR client for Radarr is connected and waiting for events.|
2025-05-08 15:02:31|INFO    |root                            |Successful authentication from ***.***.***.*** for user n30x|
2025-05-08 15:03:19|INFO    |root                            |BAZARR All providers are throttled|
2025-05-08 15:03:24|INFO    |root                            |BAZARR All providers are throttled|
2025-05-08 15:14:18|ERROR   |engineio.server                 |Invalid session LYH3FVUNH_yt99bUAAAm (further occurrences of this error will be logged with level INFO)|
2025-05-08 16:26:42|INFO    |root                            |Successful authentication from ***.***.***.*** for user n30x|
2025-05-08 16:27:18|INFO    |root                            |BAZARR throttled providers have been reset (only AuthenticationError, ConfigurationError and PaymentRequired).|
2025-05-08 16:27:18|INFO    |root                            |BAZARR throttled providers have been reset (only AuthenticationError, ConfigurationError and PaymentRequired).|
2025-05-08 16:27:18|INFO    |root                            |BAZARR throttled providers have been reset (only AuthenticationError, ConfigurationError and PaymentRequired).|
2025-05-08 16:27:18|INFO    |root                            |BAZARR throttled providers have been reset (only AuthenticationError, ConfigurationError and PaymentRequired).|
2025-05-08 16:31:19|INFO    |root                            |Provider opensubtitlescom throttle count 1 of 5, waiting 5sec and trying again|
2025-05-08 16:33:54|INFO    |root                            |Bazarr is being restarted...|
2025-05-08 16:33:58|ERROR   |root                            |BAZARR cannot bind to specified IP, trying with ***.***.***.***|'Traceback (most recent call last):\n  File "/app/bazarr/bin/bazarr/app/server.py", line 46, in configure_server\n    self.server = create_server(app,\n                  ^^^^^^^^^^^^^^^^^^\n  File "/app/bazarr/bin/bazarr/../libs/waitress/server.py", line 78, in create_server\n    last_serv = TcpWSGIServer(\n                ^^^^^^^^^^^^^^\n  File "/app/bazarr/bin/bazarr/../libs/waitress/server.py", line 243, in __init__\n    self.bind_server_socket()\n  File "/app/bazarr/bin/bazarr/../libs/waitress/server.py", line 364, in bind_server_socket\n    self.bind(sockaddr)\n  File "/app/bazarr/bin/bazarr/../libs/waitress/wasyncore.py", line 395, in bind\n    return self.socket.bind(addr)\n           ^^^^^^^^^^^^^^^^^^^^^^\nOSError: [Errno 99] Address not available'|
2025-05-08 16:33:59|INFO    |root                            |BAZARR trying to connect to Sonarr SignalR feed...|
2025-05-08 16:33:59|INFO    |root                            |BAZARR trying to connect to Radarr SignalR feed...|
2025-05-08 16:33:59|INFO    |waitress                        |BAZARR is started and waiting for requests on: http://***.***.***.***:6767|
2025-05-08 16:33:59|INFO    |root                            |BAZARR SignalR client for Radarr is connected and waiting for events.|
2025-05-08 16:33:59|INFO    |root                            |BAZARR SignalR client for Sonarr is connected and waiting for events.|
2025-05-08 16:37:50|INFO    |root                            |Throttling subdivx for 10 minutes, until 25/05/08 16:47, because of: HTTPError. Exception info: "'403 Client Error: Forbidden for url: https://www.subdivx.com/inc/ajax.php' ~ subdivx.py@209"|
2025-05-08 16:42:32|INFO    |root                            |BAZARR Finished searching for missing Movies Subtitles. Check History for more information.|
2025-05-08 16:47:29|INFO    |root                            |Throttling opensubtitlescom for 6 hours, until 25/05/08 22:47, because of: DownloadLimitExceeded. Exception info: "'Daily download limit reached. 21 subtitles have been downloaded and -1 r' ~ opensubtitlescom.py@543"|
2025-05-08 16:47:37|INFO    |root                            |BAZARR Finished searching for missing Series Subtitles. Check History for more information.|
2025-05-08 16:51:29|INFO    |root                            |BAZARR Finished searching for missing Series Subtitles. Check History for more information.|
2025-05-08 18:11:23|ERROR   |root                            |BAZARR SignalR client for Sonarr connection as been lost. Trying to reconnect...|
2025-05-08 18:11:23|ERROR   |root                            |BAZARR SignalR client for Radarr connection as been lost. Trying to reconnect...|
2025-05-08 18:19:05|ERROR   |root                            |BAZARR Error trying to get rootfolder from Sonarr. Connection Error.|'Traceback (most recent call last):\n  File "/app/bazarr/bin/bazarr/../libs/urllib3/connection.py", line 198, in _new_conn\n    sock = connection.create_connection(\n           ^^^^^^^^^^^^^^^^^^^^^^^^^^^^^\n  File "/app/bazarr/bin/bazarr/../custom_libs/subliminal_patch/http.py", line 325, in patched_create_connection\n    return _orig_create_connection(address, *args, **kwargs)\n           ^^^^^^^^^^^^^^^^^^^^^^^^^^^^^^^^^^^^^^^^^^^^^^^^^\n  File "/app/bazarr/bin/bazarr/../libs/urllib3/util/connection.py", line 85, in create_connection\n    raise err\n  File "/app/bazarr/bin/bazarr/../libs/urllib3/util/connection.py", line 73, in create_connection\n    sock.connect(sa)\nConnectionRefusedError: [Errno 111] Connection refused\n\nThe above exception was the direct cause of the following exception:\n\nTraceback (most recent call last):\n  File "/app/bazarr/bin/bazarr/../libs/urllib3/connectionpool.py", line 793, in urlopen\n    response = self._make_request(\n               ^^^^^^^^^^^^^^^^^^^\n  File "/app/bazarr/bin/bazarr/../libs/urllib3/connectionpool.py", line 496, in _make_request\n    conn.request(\n  File "/app/bazarr/bin/bazarr/../libs/urllib3/connection.py", line 400, in request\n    self.endheaders()\n  File "/usr/lib/python3.12/http/client.py", line 1333, in endheaders\n    self._send_output(message_body, encode_chunked=encode_chunked)\n  File "/usr/lib/python3.12/http/client.py", line 1093, in _send_output\n    self.send(msg)\n  File "/usr/lib/python3.12/http/client.py", line 1037, in send\n    self.connect()\n  File "/app/bazarr/bin/bazarr/../libs/urllib3/connection.py", line 238, in connect\n    self.sock = self._new_conn()\n                ^^^^^^^^^^^^^^^^\n  File "/app/bazarr/bin/bazarr/../libs/urllib3/connection.py", line 213, in _new_conn\n    raise NewConnectionError(\nurllib3.exceptions.NewConnectionError: <urllib3.connection.HTTPConnection object at 0x7f7d63108ec0>: Failed to establish a new connection: [Errno 111] Connection refused\n\nThe above exception was the direct cause of the following exception:\n\nTraceback (most recent call last):\n  File "/app/bazarr/bin/bazarr/../libs/requests/adapters.py", line 486, in send\n    resp = conn.urlopen(\n           ^^^^^^^^^^^^^\n  File "/app/bazarr/bin/bazarr/../libs/urllib3/connectionpool.py", line 847, in urlopen\n    retries = retries.increment(\n              ^^^^^^^^^^^^^^^^^^\n  File "/app/bazarr/bin/bazarr/../libs/urllib3/util/retry.py", line 515, in increment\n    raise MaxRetryError(_pool, url, reason) from reason  # type: ignore[arg-type]\n    ^^^^^^^^^^^^^^^^^^^^^^^^^^^^^^^^^^^^^^^^^^^^^^^^^^^\nurllib3.exceptions.MaxRetryError: HTTPConnectionPool(host=\'***.***.***.***\', port=8989): Max retries exceeded with url: /api/v3/rootfolder?apikey=(removed) (Caused by NewConnectionError(\'<urllib3.connection.HTTPConnection object at 0x7f7d63108ec0>: Failed to establish a new connection: [Errno 111] Connection refused\'))\n\nDuring handling of the above exception, another exception occurred:\n\nTraceback (most recent call last):\n  File "/app/bazarr/bin/bazarr/sonarr/rootfolder.py", line 22, in get_sonarr_rootfolder\n    rootfolder = requests.get(url_sonarr_api_rootfolder, timeout=int(settings.sonarr.http_timeout), verify=False, headers=HEADERS)\n                 ^^^^^^^^^^^^^^^^^^^^^^^^^^^^^^^^^^^^^^^^^^^^^^^^^^^^^^^^^^^^^^^^^^^^^^^^^^^^^^^^^^^^^^^^^^^^^^^^^^^^^^^^^^^^^^^^^\n  File "/app/bazarr/bin/bazarr/../libs/requests/api.py", line 73, in get\n    return request("get", url, params=params, **kwargs)\n           ^^^^^^^^^^^^^^^^^^^^^^^^^^^^^^^^^^^^^^^^^^^^\n  File "/app/bazarr/bin/bazarr/../libs/requests/api.py", line 59, in request\n    return session.request(method=method, url=url, **kwargs)\n           ^^^^^^^^^^^^^^^^^^^^^^^^^^^^^^^^^^^^^^^^^^^^^^^^^\n  File "/app/bazarr/bin/bazarr/../libs/requests/sessions.py", line 589, in request\n    resp = self.send(prep, **send_kwargs)\n           ^^^^^^^^^^^^^^^^^^^^^^^^^^^^^^\n  File "/app/bazarr/bin/bazarr/../libs/requests/sessions.py", line 703, in send\n    r = adapter.send(request, **kwargs)\n        ^^^^^^^^^^^^^^^^^^^^^^^^^^^^^^^\n  File "/app/bazarr/bin/bazarr/../libs/requests/adapters.py", line 519, in send\n    raise ConnectionError(e, request=request)\nrequests.exceptions.ConnectionError: HTTPConnectionPool(host=\'***.***.***.***\', port=8989): Max retries exceeded with url: /api/v3/rootfolder?apikey=(removed) (Caused by NewConnectionError(\'<urllib3.connection.HTTPConnection object at 0x7f7d63108ec0>: Failed to establish a new connection: [Errno 111] Connection refused\'))'|
2025-05-08 18:19:26|ERROR   |root                            |BAZARR Error trying to get tags from Sonarr. Connection Error.|'Traceback (most recent call last):\n  File "/app/bazarr/bin/bazarr/../libs/urllib3/connection.py", line 198, in _new_conn\n    sock = connection.create_connection(\n           ^^^^^^^^^^^^^^^^^^^^^^^^^^^^^\n  File "/app/bazarr/bin/bazarr/../custom_libs/subliminal_patch/http.py", line 325, in patched_create_connection\n    return _orig_create_connection(address, *args, **kwargs)\n           ^^^^^^^^^^^^^^^^^^^^^^^^^^^^^^^^^^^^^^^^^^^^^^^^^\n  File "/app/bazarr/bin/bazarr/../libs/urllib3/util/connection.py", line 85, in create_connection\n    raise err\n  File "/app/bazarr/bin/bazarr/../libs/urllib3/util/connection.py", line 73, in create_connection\n    sock.connect(sa)\nConnectionRefusedError: [Errno 111] Connection refused\n\nThe above exception was the direct cause of the following exception:\n\nTraceback (most recent call last):\n  File "/app/bazarr/bin/bazarr/../libs/urllib3/connectionpool.py", line 793, in urlopen\n    response = self._make_request(\n               ^^^^^^^^^^^^^^^^^^^\n  File "/app/bazarr/bin/bazarr/../libs/urllib3/connectionpool.py", line 496, in _make_request\n    conn.request(\n  File "/app/bazarr/bin/bazarr/../libs/urllib3/connection.py", line 400, in request\n    self.endheaders()\n  File "/usr/lib/python3.12/http/client.py", line 1333, in endheaders\n    self._send_output(message_body, encode_chunked=encode_chunked)\n  File "/usr/lib/python3.12/http/client.py", line 1093, in _send_output\n    self.send(msg)\n  File "/usr/lib/python3.12/http/client.py", line 1037, in send\n    self.connect()\n  File "/app/bazarr/bin/bazarr/../libs/urllib3/connection.py", line 238, in connect\n    self.sock = self._new_conn()\n                ^^^^^^^^^^^^^^^^\n  File "/app/bazarr/bin/bazarr/../libs/urllib3/connection.py", line 213, in _new_conn\n    raise NewConnectionError(\nurllib3.exceptions.NewConnectionError: <urllib3.connection.HTTPConnection object at 0x7f7d63286b70>: Failed to establish a new connection: [Errno 111] Connection refused\n\nThe above exception was the direct cause of the following exception:\n\nTraceback (most recent call last):\n  File "/app/bazarr/bin/bazarr/../libs/requests/adapters.py", line 486, in send\n    resp = conn.urlopen(\n           ^^^^^^^^^^^^^\n  File "/app/bazarr/bin/bazarr/../libs/urllib3/connectionpool.py", line 847, in urlopen\n    retries = retries.increment(\n              ^^^^^^^^^^^^^^^^^^\n  File "/app/bazarr/bin/bazarr/../libs/urllib3/util/retry.py", line 515, in increment\n    raise MaxRetryError(_pool, url, reason) from reason  # type: ignore[arg-type]\n    ^^^^^^^^^^^^^^^^^^^^^^^^^^^^^^^^^^^^^^^^^^^^^^^^^^^\nurllib3.exceptions.MaxRetryError: HTTPConnectionPool(host=\'***.***.***.***\', port=8989): Max retries exceeded with url: /api/v3/tag?apikey=(removed) (Caused by NewConnectionError(\'<urllib3.connection.HTTPConnection object at 0x7f7d63286b70>: Failed to establish a new connection: [Errno 111] Connection refused\'))\n\nDuring handling of the above exception, another exception occurred:\n\nTraceback (most recent call last):\n  File "/app/bazarr/bin/bazarr/sonarr/sync/utils.py", line 56, in get_tags\n    tagsDict = requests.get(url_sonarr_api_series, timeout=int(settings.sonarr.http_timeout), verify=False, headers=HEADERS)\n               ^^^^^^^^^^^^^^^^^^^^^^^^^^^^^^^^^^^^^^^^^^^^^^^^^^^^^^^^^^^^^^^^^^^^^^^^^^^^^^^^^^^^^^^^^^^^^^^^^^^^^^^^^^^^^\n  File "/app/bazarr/bin/bazarr/../libs/requests/api.py", line 73, in get\n    return request("get", url, params=params, **kwargs)\n           ^^^^^^^^^^^^^^^^^^^^^^^^^^^^^^^^^^^^^^^^^^^^\n  File "/app/bazarr/bin/bazarr/../libs/requests/api.py", line 59, in request\n    return session.request(method=method, url=url, **kwargs)\n           ^^^^^^^^^^^^^^^^^^^^^^^^^^^^^^^^^^^^^^^^^^^^^^^^^\n  File "/app/bazarr/bin/bazarr/../libs/requests/sessions.py", line 589, in request\n    resp = self.send(prep, **send_kwargs)\n           ^^^^^^^^^^^^^^^^^^^^^^^^^^^^^^\n  File "/app/bazarr/bin/bazarr/../libs/requests/sessions.py", line 703, in send\n    r = adapter.send(request, **kwargs)\n        ^^^^^^^^^^^^^^^^^^^^^^^^^^^^^^^\n  File "/app/bazarr/bin/bazarr/../libs/requests/adapters.py", line 519, in send\n    raise ConnectionError(e, request=request)\nrequests.exceptions.ConnectionError: HTTPConnectionPool(host=\'***.***.***.***\', port=8989): Max retries exceeded with url: /api/v3/tag?apikey=(removed) (Caused by NewConnectionError(\'<urllib3.connection.HTTPConnection object at 0x7f7d63286b70>: Failed to establish a new connection: [Errno 111] Connection refused\'))'|
2025-05-08 18:19:47|ERROR   |root                            |BAZARR Error trying to get series from Sonarr. Connection Error.|'Traceback (most recent call last):\n  File "/app/bazarr/bin/bazarr/../libs/urllib3/connection.py", line 198, in _new_conn\n    sock = connection.create_connection(\n           ^^^^^^^^^^^^^^^^^^^^^^^^^^^^^\n  File "/app/bazarr/bin/bazarr/../custom_libs/subliminal_patch/http.py", line 325, in patched_create_connection\n    return _orig_create_connection(address, *args, **kwargs)\n           ^^^^^^^^^^^^^^^^^^^^^^^^^^^^^^^^^^^^^^^^^^^^^^^^^\n  File "/app/bazarr/bin/bazarr/../libs/urllib3/util/connection.py", line 85, in create_connection\n    raise err\n  File "/app/bazarr/bin/bazarr/../libs/urllib3/util/connection.py", line 73, in create_connection\n    sock.connect(sa)\nConnectionRefusedError: [Errno 111] Connection refused\n\nThe above exception was the direct cause of the following exception:\n\nTraceback (most recent call last):\n  File "/app/bazarr/bin/bazarr/../libs/urllib3/connectionpool.py", line 793, in urlopen\n    response = self._make_request(\n               ^^^^^^^^^^^^^^^^^^^\n  File "/app/bazarr/bin/bazarr/../libs/urllib3/connectionpool.py", line 496, in _make_request\n    conn.request(\n  File "/app/bazarr/bin/bazarr/../libs/urllib3/connection.py", line 400, in request\n    self.endheaders()\n  File "/usr/lib/python3.12/http/client.py", line 1333, in endheaders\n    self._send_output(message_body, encode_chunked=encode_chunked)\n  File "/usr/lib/python3.12/http/client.py", line 1093, in _send_output\n    self.send(msg)\n  File "/usr/lib/python3.12/http/client.py", line 1037, in send\n    self.connect()\n  File "/app/bazarr/bin/bazarr/../libs/urllib3/connection.py", line 238, in connect\n    self.sock = self._new_conn()\n                ^^^^^^^^^^^^^^^^\n  File "/app/bazarr/bin/bazarr/../libs/urllib3/connection.py", line 213, in _new_conn\n    raise NewConnectionError(\nurllib3.exceptions.NewConnectionError: <urllib3.connection.HTTPConnection object at 0x7f7d63109190>: Failed to establish a new connection: [Errno 111] Connection refused\n\nThe above exception was the direct cause of the following exception:\n\nTraceback (most recent call last):\n  File "/app/bazarr/bin/bazarr/../libs/requests/adapters.py", line 486, in send\n    resp = conn.urlopen(\n           ^^^^^^^^^^^^^\n  File "/app/bazarr/bin/bazarr/../libs/urllib3/connectionpool.py", line 847, in urlopen\n    retries = retries.increment(\n              ^^^^^^^^^^^^^^^^^^\n  File "/app/bazarr/bin/bazarr/../libs/urllib3/util/retry.py", line 515, in increment\n    raise MaxRetryError(_pool, url, reason) from reason  # type: ignore[arg-type]\n    ^^^^^^^^^^^^^^^^^^^^^^^^^^^^^^^^^^^^^^^^^^^^^^^^^^^\nurllib3.exceptions.MaxRetryError: HTTPConnectionPool(host=\'***.***.***.***\', port=8989): Max retries exceeded with url: /api/v3/series/?apikey=(removed) (Caused by NewConnectionError(\'<urllib3.connection.HTTPConnection object at 0x7f7d63109190>: Failed to establish a new connection: [Errno 111] Connection refused\'))\n\nDuring handling of the above exception, another exception occurred:\n\nTraceback (most recent call last):\n  File "/app/bazarr/bin/bazarr/sonarr/sync/utils.py", line 74, in get_series_from_sonarr_api\n    r = requests.get(url_sonarr_api_series, timeout=int(settings.sonarr.http_timeout), verify=False, headers=HEADERS)\n        ^^^^^^^^^^^^^^^^^^^^^^^^^^^^^^^^^^^^^^^^^^^^^^^^^^^^^^^^^^^^^^^^^^^^^^^^^^^^^^^^^^^^^^^^^^^^^^^^^^^^^^^^^^^^^\n  File "/app/bazarr/bin/bazarr/../libs/requests/api.py", line 73, in get\n    return request("get", url, params=params, **kwargs)\n           ^^^^^^^^^^^^^^^^^^^^^^^^^^^^^^^^^^^^^^^^^^^^\n  File "/app/bazarr/bin/bazarr/../libs/requests/api.py", line 59, in request\n    return session.request(method=method, url=url, **kwargs)\n           ^^^^^^^^^^^^^^^^^^^^^^^^^^^^^^^^^^^^^^^^^^^^^^^^^\n  File "/app/bazarr/bin/bazarr/../libs/requests/sessions.py", line 589, in request\n    resp = self.send(prep, **send_kwargs)\n           ^^^^^^^^^^^^^^^^^^^^^^^^^^^^^^\n  File "/app/bazarr/bin/bazarr/../libs/requests/sessions.py", line 703, in send\n    r = adapter.send(request, **kwargs)\n        ^^^^^^^^^^^^^^^^^^^^^^^^^^^^^^^\n  File "/app/bazarr/bin/bazarr/../libs/requests/adapters.py", line 519, in send\n    raise ConnectionError(e, request=request)\nrequests.exceptions.ConnectionError: HTTPConnectionPool(host=\'***.***.***.***\', port=8989): Max retries exceeded with url: /api/v3/series/?apikey=(removed) (Caused by NewConnectionError(\'<urllib3.connection.HTTPConnection object at 0x7f7d63109190>: Failed to establish a new connection: [Errno 111] Connection refused\'))'|
2025-05-08 18:24:09|ERROR   |root                            |BAZARR Error trying to get rootfolder from Radarr. Connection Error.|'Traceback (most recent call last):\n  File "/app/bazarr/bin/bazarr/../libs/urllib3/connection.py", line 198, in _new_conn\n    sock = connection.create_connection(\n           ^^^^^^^^^^^^^^^^^^^^^^^^^^^^^\n  File "/app/bazarr/bin/bazarr/../custom_libs/subliminal_patch/http.py", line 325, in patched_create_connection\n    return _orig_create_connection(address, *args, **kwargs)\n           ^^^^^^^^^^^^^^^^^^^^^^^^^^^^^^^^^^^^^^^^^^^^^^^^^\n  File "/app/bazarr/bin/bazarr/../libs/urllib3/util/connection.py", line 85, in create_connection\n    raise err\n  File "/app/bazarr/bin/bazarr/../libs/urllib3/util/connection.py", line 73, in create_connection\n    sock.connect(sa)\nConnectionRefusedError: [Errno 111] Connection refused\n\nThe above exception was the direct cause of the following exception:\n\nTraceback (most recent call last):\n  File "/app/bazarr/bin/bazarr/../libs/urllib3/connectionpool.py", line 793, in urlopen\n    response = self._make_request(\n               ^^^^^^^^^^^^^^^^^^^\n  File "/app/bazarr/bin/bazarr/../libs/urllib3/connectionpool.py", line 496, in _make_request\n    conn.request(\n  File "/app/bazarr/bin/bazarr/../libs/urllib3/connection.py", line 400, in request\n    self.endheaders()\n  File "/usr/lib/python3.12/http/client.py", line 1333, in endheaders\n    self._send_output(message_body, encode_chunked=encode_chunked)\n  File "/usr/lib/python3.12/http/client.py", line 1093, in _send_output\n    self.send(msg)\n  File "/usr/lib/python3.12/http/client.py", line 1037, in send\n    self.connect()\n  File "/app/bazarr/bin/bazarr/../libs/urllib3/connection.py", line 238, in connect\n    self.sock = self._new_conn()\n                ^^^^^^^^^^^^^^^^\n  File "/app/bazarr/bin/bazarr/../libs/urllib3/connection.py", line 213, in _new_conn\n    raise NewConnectionError(\nurllib3.exceptions.NewConnectionError: <urllib3.connection.HTTPConnection object at 0x7f7d632a40e0>: Failed to establish a new connection: [Errno 111] Connection refused\n\nThe above exception was the direct cause of the following exception:\n\nTraceback (most recent call last):\n  File "/app/bazarr/bin/bazarr/../libs/requests/adapters.py", line 486, in send\n    resp = conn.urlopen(\n           ^^^^^^^^^^^^^\n  File "/app/bazarr/bin/bazarr/../libs/urllib3/connectionpool.py", line 847, in urlopen\n    retries = retries.increment(\n              ^^^^^^^^^^^^^^^^^^\n  File "/app/bazarr/bin/bazarr/../libs/urllib3/util/retry.py", line 515, in increment\n    raise MaxRetryError(_pool, url, reason) from reason  # type: ignore[arg-type]\n    ^^^^^^^^^^^^^^^^^^^^^^^^^^^^^^^^^^^^^^^^^^^^^^^^^^^\nurllib3.exceptions.MaxRetryError: HTTPConnectionPool(host=\'***.***.***.***\', port=7878): Max retries exceeded with url: /api/v3/rootfolder?apikey=(removed) (Caused by NewConnectionError(\'<urllib3.connection.HTTPConnection object at 0x7f7d632a40e0>: Failed to establish a new connection: [Errno 111] Connection refused\'))\n\nDuring handling of the above exception, another exception occurred:\n\nTraceback (most recent call last):\n  File "/app/bazarr/bin/bazarr/radarr/rootfolder.py", line 22, in get_radarr_rootfolder\n    rootfolder = requests.get(url_radarr_api_rootfolder, timeout=int(settings.radarr.http_timeout), verify=False, headers=HEADERS)\n                 ^^^^^^^^^^^^^^^^^^^^^^^^^^^^^^^^^^^^^^^^^^^^^^^^^^^^^^^^^^^^^^^^^^^^^^^^^^^^^^^^^^^^^^^^^^^^^^^^^^^^^^^^^^^^^^^^^\n  File "/app/bazarr/bin/bazarr/../libs/requests/api.py", line 73, in get\n    return request("get", url, params=params, **kwargs)\n           ^^^^^^^^^^^^^^^^^^^^^^^^^^^^^^^^^^^^^^^^^^^^\n  File "/app/bazarr/bin/bazarr/../libs/requests/api.py", line 59, in request\n    return session.request(method=method, url=url, **kwargs)\n           ^^^^^^^^^^^^^^^^^^^^^^^^^^^^^^^^^^^^^^^^^^^^^^^^^\n  File "/app/bazarr/bin/bazarr/../libs/requests/sessions.py", line 589, in request\n    resp = self.send(prep, **send_kwargs)\n           ^^^^^^^^^^^^^^^^^^^^^^^^^^^^^^\n  File "/app/bazarr/bin/bazarr/../libs/requests/sessions.py", line 703, in send\n    r = adapter.send(request, **kwargs)\n        ^^^^^^^^^^^^^^^^^^^^^^^^^^^^^^^\n  File "/app/bazarr/bin/bazarr/../libs/requests/adapters.py", line 519, in send\n    raise ConnectionError(e, request=request)\nrequests.exceptions.ConnectionError: HTTPConnectionPool(host=\'***.***.***.***\', port=7878): Max retries exceeded with url: /api/v3/rootfolder?apikey=(removed) (Caused by NewConnectionError(\'<urllib3.connection.HTTPConnection object at 0x7f7d632a40e0>: Failed to establish a new connection: [Errno 111] Connection refused\'))'|
2025-05-08 18:24:30|ERROR   |root                            |BAZARR Error trying to get profiles from Radarr. Connection Error.|'Traceback (most recent call last):\n  File "/app/bazarr/bin/bazarr/../libs/urllib3/connection.py", line 198, in _new_conn\n    sock = connection.create_connection(\n           ^^^^^^^^^^^^^^^^^^^^^^^^^^^^^\n  File "/app/bazarr/bin/bazarr/../custom_libs/subliminal_patch/http.py", line 325, in patched_create_connection\n    return _orig_create_connection(address, *args, **kwargs)\n           ^^^^^^^^^^^^^^^^^^^^^^^^^^^^^^^^^^^^^^^^^^^^^^^^^\n  File "/app/bazarr/bin/bazarr/../libs/urllib3/util/connection.py", line 85, in create_connection\n    raise err\n  File "/app/bazarr/bin/bazarr/../libs/urllib3/util/connection.py", line 73, in create_connection\n    sock.connect(sa)\nConnectionRefusedError: [Errno 111] Connection refused\n\nThe above exception was the direct cause of the following exception:\n\nTraceback (most recent call last):\n  File "/app/bazarr/bin/bazarr/../libs/urllib3/connectionpool.py", line 793, in urlopen\n    response = self._make_request(\n               ^^^^^^^^^^^^^^^^^^^\n  File "/app/bazarr/bin/bazarr/../libs/urllib3/connectionpool.py", line 496, in _make_request\n    conn.request(\n  File "/app/bazarr/bin/bazarr/../libs/urllib3/connection.py", line 400, in request\n    self.endheaders()\n  File "/usr/lib/python3.12/http/client.py", line 1333, in endheaders\n    self._send_output(message_body, encode_chunked=encode_chunked)\n  File "/usr/lib/python3.12/http/client.py", line 1093, in _send_output\n    self.send(msg)\n  File "/usr/lib/python3.12/http/client.py", line 1037, in send\n    self.connect()\n  File "/app/bazarr/bin/bazarr/../libs/urllib3/connection.py", line 238, in connect\n    self.sock = self._new_conn()\n                ^^^^^^^^^^^^^^^^\n  File "/app/bazarr/bin/bazarr/../libs/urllib3/connection.py", line 213, in _new_conn\n    raise NewConnectionError(\nurllib3.exceptions.NewConnectionError: <urllib3.connection.HTTPConnection object at 0x7f7d6606d3a0>: Failed to establish a new connection: [Errno 111] Connection refused\n\nThe above exception was the direct cause of the following exception:\n\nTraceback (most recent call last):\n  File "/app/bazarr/bin/bazarr/../libs/requests/adapters.py", line 486, in send\n    resp = conn.urlopen(\n           ^^^^^^^^^^^^^\n  File "/app/bazarr/bin/bazarr/../libs/urllib3/connectionpool.py", line 847, in urlopen\n    retries = retries.increment(\n              ^^^^^^^^^^^^^^^^^^\n  File "/app/bazarr/bin/bazarr/../libs/urllib3/util/retry.py", line 515, in increment\n    raise MaxRetryError(_pool, url, reason) from reason  # type: ignore[arg-type]\n    ^^^^^^^^^^^^^^^^^^^^^^^^^^^^^^^^^^^^^^^^^^^^^^^^^^^\nurllib3.exceptions.MaxRetryError: HTTPConnectionPool(host=\'***.***.***.***\', port=7878): Max retries exceeded with url: /api/v3/qualityprofile?apikey=(removed) (Caused by NewConnectionError(\'<urllib3.connection.HTTPConnection object at 0x7f7d6606d3a0>: Failed to establish a new connection: [Errno 111] Connection refused\'))\n\nDuring handling of the above exception, another exception occurred:\n\nTraceback (most recent call last):\n  File "/app/bazarr/bin/bazarr/radarr/sync/utils.py", line 19, in get_profile_list\n    profiles_json = requests.get(url_radarr_api_movies, timeout=int(settings.radarr.http_timeout), verify=False, headers=HEADERS)\n                    ^^^^^^^^^^^^^^^^^^^^^^^^^^^^^^^^^^^^^^^^^^^^^^^^^^^^^^^^^^^^^^^^^^^^^^^^^^^^^^^^^^^^^^^^^^^^^^^^^^^^^^^^^^^^^\n  File "/app/bazarr/bin/bazarr/../libs/requests/api.py", line 73, in get\n    return request("get", url, params=params, **kwargs)\n           ^^^^^^^^^^^^^^^^^^^^^^^^^^^^^^^^^^^^^^^^^^^^\n  File "/app/bazarr/bin/bazarr/../libs/requests/api.py", line 59, in request\n    return session.request(method=method, url=url, **kwargs)\n           ^^^^^^^^^^^^^^^^^^^^^^^^^^^^^^^^^^^^^^^^^^^^^^^^^\n  File "/app/bazarr/bin/bazarr/../libs/requests/sessions.py", line 589, in request\n    resp = self.send(prep, **send_kwargs)\n           ^^^^^^^^^^^^^^^^^^^^^^^^^^^^^^\n  File "/app/bazarr/bin/bazarr/../libs/requests/sessions.py", line 703, in send\n    r = adapter.send(request, **kwargs)\n        ^^^^^^^^^^^^^^^^^^^^^^^^^^^^^^^\n  File "/app/bazarr/bin/bazarr/../libs/requests/adapters.py", line 519, in send\n    raise ConnectionError(e, request=request)\nrequests.exceptions.ConnectionError: HTTPConnectionPool(host=\'***.***.***.***\', port=7878): Max retries exceeded with url: /api/v3/qualityprofile?apikey=(removed) (Caused by NewConnectionError(\'<urllib3.connection.HTTPConnection object at 0x7f7d6606d3a0>: Failed to establish a new connection: [Errno 111] Connection refused\'))'|
2025-05-08 18:24:42|ERROR   |root                            |BAZARR Error trying to get tags from Radarr. Connection Error.|'Traceback (most recent call last):\n  File "/app/bazarr/bin/bazarr/../libs/urllib3/connection.py", line 198, in _new_conn\n    sock = connection.create_connection(\n           ^^^^^^^^^^^^^^^^^^^^^^^^^^^^^\n  File "/app/bazarr/bin/bazarr/../custom_libs/subliminal_patch/http.py", line 325, in patched_create_connection\n    return _orig_create_connection(address, *args, **kwargs)\n           ^^^^^^^^^^^^^^^^^^^^^^^^^^^^^^^^^^^^^^^^^^^^^^^^^\n  File "/app/bazarr/bin/bazarr/../libs/urllib3/util/connection.py", line 85, in create_connection\n    raise err\n  File "/app/bazarr/bin/bazarr/../libs/urllib3/util/connection.py", line 73, in create_connection\n    sock.connect(sa)\nConnectionRefusedError: [Errno 111] Connection refused\n\nThe above exception was the direct cause of the following exception:\n\nTraceback (most recent call last):\n  File "/app/bazarr/bin/bazarr/../libs/urllib3/connectionpool.py", line 793, in urlopen\n    response = self._make_request(\n               ^^^^^^^^^^^^^^^^^^^\n  File "/app/bazarr/bin/bazarr/../libs/urllib3/connectionpool.py", line 496, in _make_request\n    conn.request(\n  File "/app/bazarr/bin/bazarr/../libs/urllib3/connection.py", line 400, in request\n    self.endheaders()\n  File "/usr/lib/python3.12/http/client.py", line 1333, in endheaders\n    self._send_output(message_body, encode_chunked=encode_chunked)\n  File "/usr/lib/python3.12/http/client.py", line 1093, in _send_output\n    self.send(msg)\n  File "/usr/lib/python3.12/http/client.py", line 1037, in send\n    self.connect()\n  File "/app/bazarr/bin/bazarr/../libs/urllib3/connection.py", line 238, in connect\n    self.sock = self._new_conn()\n                ^^^^^^^^^^^^^^^^\n  File "/app/bazarr/bin/bazarr/../libs/urllib3/connection.py", line 213, in _new_conn\n    raise NewConnectionError(\nurllib3.exceptions.NewConnectionError: <urllib3.connection.HTTPConnection object at 0x7f7d632879e0>: Failed to establish a new connection: [Errno 111] Connection refused\n\nThe above exception was the direct cause of the following exception:\n\nTraceback (most recent call last):\n  File "/app/bazarr/bin/bazarr/../libs/requests/adapters.py", line 486, in send\n    resp = conn.urlopen(\n           ^^^^^^^^^^^^^\n  File "/app/bazarr/bin/bazarr/../libs/urllib3/connectionpool.py", line 847, in urlopen\n    retries = retries.increment(\n              ^^^^^^^^^^^^^^^^^^\n  File "/app/bazarr/bin/bazarr/../libs/urllib3/util/retry.py", line 515, in increment\n    raise MaxRetryError(_pool, url, reason) from reason  # type: ignore[arg-type]\n    ^^^^^^^^^^^^^^^^^^^^^^^^^^^^^^^^^^^^^^^^^^^^^^^^^^^\nurllib3.exceptions.MaxRetryError: HTTPConnectionPool(host=\'***.***.***.***\', port=7878): Max retries exceeded with url: /api/v3/tag?apikey=(removed) (Caused by NewConnectionError(\'<urllib3.connection.HTTPConnection object at 0x7f7d632879e0>: Failed to establish a new connection: [Errno 111] Connection refused\'))\n\nDuring handling of the above exception, another exception occurred:\n\nTraceback (most recent call last):\n  File "/app/bazarr/bin/bazarr/radarr/sync/utils.py", line 48, in get_tags\n    tagsDict = requests.get(url_radarr_api_series, timeout=int(settings.radarr.http_timeout), verify=False, headers=HEADERS)\n               ^^^^^^^^^^^^^^^^^^^^^^^^^^^^^^^^^^^^^^^^^^^^^^^^^^^^^^^^^^^^^^^^^^^^^^^^^^^^^^^^^^^^^^^^^^^^^^^^^^^^^^^^^^^^^\n  File "/app/bazarr/bin/bazarr/../libs/requests/api.py", line 73, in get\n    return request("get", url, params=params, **kwargs)\n           ^^^^^^^^^^^^^^^^^^^^^^^^^^^^^^^^^^^^^^^^^^^^\n  File "/app/bazarr/bin/bazarr/../libs/requests/api.py", line 59, in request\n    return session.request(method=method, url=url, **kwargs)\n           ^^^^^^^^^^^^^^^^^^^^^^^^^^^^^^^^^^^^^^^^^^^^^^^^^\n  File "/app/bazarr/bin/bazarr/../libs/requests/sessions.py", line 589, in request\n    resp = self.send(prep, **send_kwargs)\n           ^^^^^^^^^^^^^^^^^^^^^^^^^^^^^^\n  File "/app/bazarr/bin/bazarr/../libs/requests/sessions.py", line 703, in send\n    r = adapter.send(request, **kwargs)\n        ^^^^^^^^^^^^^^^^^^^^^^^^^^^^^^^\n  File "/app/bazarr/bin/bazarr/../libs/requests/adapters.py", line 519, in send\n    raise ConnectionError(e, request=request)\nrequests.exceptions.ConnectionError: HTTPConnectionPool(host=\'***.***.***.***\', port=7878): Max retries exceeded with url: /api/v3/tag?apikey=(removed) (Caused by NewConnectionError(\'<urllib3.connection.HTTPConnection object at 0x7f7d632879e0>: Failed to establish a new connection: [Errno 111] Connection refused\'))'|
2025-05-08 18:25:03|ERROR   |root                            |BAZARR Error trying to get movies from Radarr. Connection Error.|'Traceback (most recent call last):\n  File "/app/bazarr/bin/bazarr/../libs/urllib3/connection.py", line 198, in _new_conn\n    sock = connection.create_connection(\n           ^^^^^^^^^^^^^^^^^^^^^^^^^^^^^\n  File "/app/bazarr/bin/bazarr/../custom_libs/subliminal_patch/http.py", line 325, in patched_create_connection\n    return _orig_create_connection(address, *args, **kwargs)\n           ^^^^^^^^^^^^^^^^^^^^^^^^^^^^^^^^^^^^^^^^^^^^^^^^^\n  File "/app/bazarr/bin/bazarr/../libs/urllib3/util/connection.py", line 85, in create_connection\n    raise err\n  File "/app/bazarr/bin/bazarr/../libs/urllib3/util/connection.py", line 73, in create_connection\n    sock.connect(sa)\nConnectionRefusedError: [Errno 111] Connection refused\n\nThe above exception was the direct cause of the following exception:\n\nTraceback (most recent call last):\n  File "/app/bazarr/bin/bazarr/../libs/urllib3/connectionpool.py", line 793, in urlopen\n    response = self._make_request(\n               ^^^^^^^^^^^^^^^^^^^\n  File "/app/bazarr/bin/bazarr/../libs/urllib3/connectionpool.py", line 496, in _make_request\n    conn.request(\n  File "/app/bazarr/bin/bazarr/../libs/urllib3/connection.py", line 400, in request\n    self.endheaders()\n  File "/usr/lib/python3.12/http/client.py", line 1333, in endheaders\n    self._send_output(message_body, encode_chunked=encode_chunked)\n  File "/usr/lib/python3.12/http/client.py", line 1093, in _send_output\n    self.send(msg)\n  File "/usr/lib/python3.12/http/client.py", line 1037, in send\n    self.connect()\n  File "/app/bazarr/bin/bazarr/../libs/urllib3/connection.py", line 238, in connect\n    self.sock = self._new_conn()\n                ^^^^^^^^^^^^^^^^\n  File "/app/bazarr/bin/bazarr/../libs/urllib3/connection.py", line 213, in _new_conn\n    raise NewConnectionError(\nurllib3.exceptions.NewConnectionError: <urllib3.connection.HTTPConnection object at 0x7f7d63286660>: Failed to establish a new connection: [Errno 111] Connection refused\n\nThe above exception was the direct cause of the following exception:\n\nTraceback (most recent call last):\n  File "/app/bazarr/bin/bazarr/../libs/requests/adapters.py", line 486, in send\n    resp = conn.urlopen(\n           ^^^^^^^^^^^^^\n  File "/app/bazarr/bin/bazarr/../libs/urllib3/connectionpool.py", line 847, in urlopen\n    retries = retries.increment(\n              ^^^^^^^^^^^^^^^^^^\n  File "/app/bazarr/bin/bazarr/../libs/urllib3/util/retry.py", line 515, in increment\n    raise MaxRetryError(_pool, url, reason) from reason  # type: ignore[arg-type]\n    ^^^^^^^^^^^^^^^^^^^^^^^^^^^^^^^^^^^^^^^^^^^^^^^^^^^\nurllib3.exceptions.MaxRetryError: HTTPConnectionPool(host=\'***.***.***.***\', port=7878): Max retries exceeded with url: /api/v3/movie?apikey=(removed) (Caused by NewConnectionError(\'<urllib3.connection.HTTPConnection object at 0x7f7d63286660>: Failed to establish a new connection: [Errno 111] Connection refused\'))\n\nDuring handling of the above exception, another exception occurred:\n\nTraceback (most recent call last):\n  File "/app/bazarr/bin/bazarr/radarr/sync/utils.py", line 72, in get_movies_from_radarr_api\n    r = requests.get(url_radarr_api_movies, timeout=int(settings.radarr.http_timeout), verify=False, headers=HEADERS)\n        ^^^^^^^^^^^^^^^^^^^^^^^^^^^^^^^^^^^^^^^^^^^^^^^^^^^^^^^^^^^^^^^^^^^^^^^^^^^^^^^^^^^^^^^^^^^^^^^^^^^^^^^^^^^^^\n  File "/app/bazarr/bin/bazarr/../libs/requests/api.py", line 73, in get\n    return request("get", url, params=params, **kwargs)\n           ^^^^^^^^^^^^^^^^^^^^^^^^^^^^^^^^^^^^^^^^^^^^\n  File "/app/bazarr/bin/bazarr/../libs/requests/api.py", line 59, in request\n    return session.request(method=method, url=url, **kwargs)\n           ^^^^^^^^^^^^^^^^^^^^^^^^^^^^^^^^^^^^^^^^^^^^^^^^^\n  File "/app/bazarr/bin/bazarr/../libs/requests/sessions.py", line 589, in request\n    resp = self.send(prep, **send_kwargs)\n           ^^^^^^^^^^^^^^^^^^^^^^^^^^^^^^\n  File "/app/bazarr/bin/bazarr/../libs/requests/sessions.py", line 703, in send\n    r = adapter.send(request, **kwargs)\n        ^^^^^^^^^^^^^^^^^^^^^^^^^^^^^^^\n  File "/app/bazarr/bin/bazarr/../libs/requests/adapters.py", line 519, in send\n    raise ConnectionError(e, request=request)\nrequests.exceptions.ConnectionError: HTTPConnectionPool(host=\'***.***.***.***\', port=7878): Max retries exceeded with url: /api/v3/movie?apikey=(removed) (Caused by NewConnectionError(\'<urllib3.connection.HTTPConnection object at 0x7f7d63286660>: Failed to establish a new connection: [Errno 111] Connection refused\'))'|
2025-05-08 18:26:45|INFO    |root                            |BAZARR SignalR client for Sonarr is connected and waiting for events.|
2025-05-08 18:26:45|INFO    |root                            |BAZARR SignalR client for Radarr is connected and waiting for events.|
2025-05-08 18:27:06|ERROR   |root                            |BAZARR SignalR client for Sonarr connection as been lost. Trying to reconnect...|
2025-05-08 18:27:06|ERROR   |root                            |BAZARR SignalR client for Radarr connection as been lost. Trying to reconnect...|
2025-05-08 18:27:07|INFO    |root                            |BAZARR SignalR client for Sonarr is connected and waiting for events.|
2025-05-08 18:27:07|INFO    |root                            |BAZARR SignalR client for Radarr is connected and waiting for events.|
2025-05-08 22:02:32|ERROR   |root                            |BAZARR Error (Path does not exist) trying to get video information for this file: /tv/Supernatural/Season 3/Supernatural S03E11 Mystery Spot  [1080p x265 10bit Joy].mkv|'Traceback (most recent call last):\n  File "/app/bazarr/bin/bazarr/subtitles/utils.py", line 35, in get_video\n    video = parse_video(path, hints=hints, skip_hashing=skip_hashing, dry_run=False, providers=providers)\n            ^^^^^^^^^^^^^^^^^^^^^^^^^^^^^^^^^^^^^^^^^^^^^^^^^^^^^^^^^^^^^^^^^^^^^^^^^^^^^^^^^^^^^^^^^^^^^\n  File "/app/bazarr/bin/bazarr/../custom_libs/subzero/video.py", line 61, in parse_video\n    return scan_video(fn, hints=hints, dont_use_actual_file=dry_run, providers=providers,\n           ^^^^^^^^^^^^^^^^^^^^^^^^^^^^^^^^^^^^^^^^^^^^^^^^^^^^^^^^^^^^^^^^^^^^^^^^^^^^^^\n  File "/app/bazarr/bin/bazarr/../custom_libs/subliminal_patch/core.py", line 839, in scan_video\n    raise ValueError(\'Path does not exist\')\nValueError: Path does not exist'|
2025-05-08 22:02:32|ERROR   |root                            |BAZARR Error (Path does not exist) trying to get video information for this file: /tv/Supernatural/Season 3/Supernatural S03E12 Jus in Bello  [1080p x265 10bit Joy].mkv|'Traceback (most recent call last):\n  File "/app/bazarr/bin/bazarr/subtitles/utils.py", line 35, in get_video\n    video = parse_video(path, hints=hints, skip_hashing=skip_hashing, dry_run=False, providers=providers)\n            ^^^^^^^^^^^^^^^^^^^^^^^^^^^^^^^^^^^^^^^^^^^^^^^^^^^^^^^^^^^^^^^^^^^^^^^^^^^^^^^^^^^^^^^^^^^^^\n  File "/app/bazarr/bin/bazarr/../custom_libs/subzero/video.py", line 61, in parse_video\n    return scan_video(fn, hints=hints, dont_use_actual_file=dry_run, providers=providers,\n           ^^^^^^^^^^^^^^^^^^^^^^^^^^^^^^^^^^^^^^^^^^^^^^^^^^^^^^^^^^^^^^^^^^^^^^^^^^^^^^\n  File "/app/bazarr/bin/bazarr/../custom_libs/subliminal_patch/core.py", line 839, in scan_video\n    raise ValueError(\'Path does not exist\')\nValueError: Path does not exist'|
2025-05-08 22:02:32|ERROR   |root                            |BAZARR Error (Path does not exist) trying to get video information for this file: /tv/Supernatural/Season 3/Supernatural S03E13 Ghostfacers  [1080p x265 10bit Joy].mkv|'Traceback (most recent call last):\n  File "/app/bazarr/bin/bazarr/subtitles/utils.py", line 35, in get_video\n    video = parse_video(path, hints=hints, skip_hashing=skip_hashing, dry_run=False, providers=providers)\n            ^^^^^^^^^^^^^^^^^^^^^^^^^^^^^^^^^^^^^^^^^^^^^^^^^^^^^^^^^^^^^^^^^^^^^^^^^^^^^^^^^^^^^^^^^^^^^\n  File "/app/bazarr/bin/bazarr/../custom_libs/subzero/video.py", line 61, in parse_video\n    return scan_video(fn, hints=hints, dont_use_actual_file=dry_run, providers=providers,\n           ^^^^^^^^^^^^^^^^^^^^^^^^^^^^^^^^^^^^^^^^^^^^^^^^^^^^^^^^^^^^^^^^^^^^^^^^^^^^^^\n  File "/app/bazarr/bin/bazarr/../custom_libs/subliminal_patch/core.py", line 839, in scan_video\n    raise ValueError(\'Path does not exist\')\nValueError: Path does not exist'|
2025-05-08 22:02:32|ERROR   |root                            |BAZARR Error (Path does not exist) trying to get video information for this file: /tv/Supernatural/Season 3/Supernatural S03E14 Long Distance Call  [1080p x265 10bit Joy].mkv|'Traceback (most recent call last):\n  File "/app/bazarr/bin/bazarr/subtitles/utils.py", line 35, in get_video\n    video = parse_video(path, hints=hints, skip_hashing=skip_hashing, dry_run=False, providers=providers)\n            ^^^^^^^^^^^^^^^^^^^^^^^^^^^^^^^^^^^^^^^^^^^^^^^^^^^^^^^^^^^^^^^^^^^^^^^^^^^^^^^^^^^^^^^^^^^^^\n  File "/app/bazarr/bin/bazarr/../custom_libs/subzero/video.py", line 61, in parse_video\n    return scan_video(fn, hints=hints, dont_use_actual_file=dry_run, providers=providers,\n           ^^^^^^^^^^^^^^^^^^^^^^^^^^^^^^^^^^^^^^^^^^^^^^^^^^^^^^^^^^^^^^^^^^^^^^^^^^^^^^\n  File "/app/bazarr/bin/bazarr/../custom_libs/subliminal_patch/core.py", line 839, in scan_video\n    raise ValueError(\'Path does not exist\')\nValueError: Path does not exist'|
2025-05-08 22:02:32|ERROR   |root                            |BAZARR Error (Path does not exist) trying to get video information for this file: /tv/Supernatural/Season 3/Supernatural S03E15 Time Is on My Side  [1080p x265 10bit Joy].mkv|'Traceback (most recent call last):\n  File "/app/bazarr/bin/bazarr/subtitles/utils.py", line 35, in get_video\n    video = parse_video(path, hints=hints, skip_hashing=skip_hashing, dry_run=False, providers=providers)\n            ^^^^^^^^^^^^^^^^^^^^^^^^^^^^^^^^^^^^^^^^^^^^^^^^^^^^^^^^^^^^^^^^^^^^^^^^^^^^^^^^^^^^^^^^^^^^^\n  File "/app/bazarr/bin/bazarr/../custom_libs/subzero/video.py", line 61, in parse_video\n    return scan_video(fn, hints=hints, dont_use_actual_file=dry_run, providers=providers,\n           ^^^^^^^^^^^^^^^^^^^^^^^^^^^^^^^^^^^^^^^^^^^^^^^^^^^^^^^^^^^^^^^^^^^^^^^^^^^^^^\n  File "/app/bazarr/bin/bazarr/../custom_libs/subliminal_patch/core.py", line 839, in scan_video\n    raise ValueError(\'Path does not exist\')\nValueError: Path does not exist'|
2025-05-08 22:02:32|ERROR   |root                            |BAZARR Error (Path does not exist) trying to get video information for this file: /tv/Supernatural/Season 3/Supernatural S03E16 No Rest for the Wicked  [1080p x265 10bit Joy].mkv|'Traceback (most recent call last):\n  File "/app/bazarr/bin/bazarr/subtitles/utils.py", line 35, in get_video\n    video = parse_video(path, hints=hints, skip_hashing=skip_hashing, dry_run=False, providers=providers)\n            ^^^^^^^^^^^^^^^^^^^^^^^^^^^^^^^^^^^^^^^^^^^^^^^^^^^^^^^^^^^^^^^^^^^^^^^^^^^^^^^^^^^^^^^^^^^^^\n  File "/app/bazarr/bin/bazarr/../custom_libs/subzero/video.py", line 61, in parse_video\n    return scan_video(fn, hints=hints, dont_use_actual_file=dry_run, providers=providers,\n           ^^^^^^^^^^^^^^^^^^^^^^^^^^^^^^^^^^^^^^^^^^^^^^^^^^^^^^^^^^^^^^^^^^^^^^^^^^^^^^\n  File "/app/bazarr/bin/bazarr/../custom_libs/subliminal_patch/core.py", line 839, in scan_video\n    raise ValueError(\'Path does not exist\')\nValueError: Path does not exist'|
2025-05-08 22:02:32|INFO    |root                            |BAZARR Finished searching for missing Series Subtitles. Check History for more information.|
2025-05-08 22:08:52|INFO    |root                            |BAZARR Finished searching for missing Movies Subtitles. Check History for more information.|
2025-05-08 23:52:19|ERROR   |root                            |BAZARR SignalR client for Radarr connection as been lost. Trying to reconnect...|
2025-05-08 23:52:23|ERROR   |root                            |BAZARR SignalR client for Sonarr connection as been lost. Trying to reconnect...|
2025-05-08 23:58:25|INFO    |root                            |BAZARR SignalR client for Radarr is connected and waiting for events.|
2025-05-08 23:58:26|INFO    |root                            |BAZARR SignalR client for Sonarr is connected and waiting for events.|
